<?xml version="1.0" ?>
<!-- =================================================================================== -->
<!-- |    This document was autogenerated by xacro from xarm_device.urdf.xacro         | -->
<!-- |    EDITING THIS FILE BY HAND IS NOT RECOMMENDED                                 | -->
<!-- =================================================================================== -->
<robot name="uflite_gripper">
  <!-- Insert at the beginning of xarm_device_macro.xacro -->
  <material name="Black">
    <color rgba="0.0 0.0 0.0 1.0"/>
  </material>
  <material name="Red">
    <color rgba="0.8 0.0 0.0 1.0"/>
  </material>
  <material name="White">
    <color rgba="1.0 1.0 1.0 1.0"/>
  </material>
  <material name="Silver">
    <color rgba="0.753 0.753 0.753 1.0"/>
  </material>
  <link name="uflite_gripper_link">
    <inertial>
      <origin rpy="0 0 0" xyz="0.0 0.0 0.030"/>
      <mass value="0.25"/>
      <inertia ixx="0.00047106" ixy="3.9292E-07" ixz="2.6537E-06" iyy="0.00033072" iyz="-1.0975E-05" izz="0.00025642"/>
    </inertial>
    <visual>
      <geometry>
        <mesh filename="package://xarm_description/meshes/gripper/lite/visual/shell.stl"/>
      </geometry>
      <origin rpy="0 0 0" xyz="0 0 0"/>
      <material name="White"/>
    </visual>
    <collision>
      <geometry>
        <mesh filename="package://xarm_description/meshes/gripper/lite/collision/shell.stl"/>
      </geometry>
      <origin rpy="0 0 0" xyz="0 0 0"/>
    </collision>
  </link>
  <joint name="finger_joint1" type="prismatic">
    <parent link="uflite_gripper_link"/>
    <child link="uflite_finger1"/>
    <origin rpy="0 0 0" xyz="0 0 0.0543"/>
    <axis xyz="0 1 0"/>
    <limit effort="5" lower="0" upper="0.0089" velocity="2"/>
  </joint>
  <link name="uflite_finger1">
    <inertial>
      <origin rpy="0 0 0" xyz="0.0 0.01 0.0086"/>
      <mass value="0.0163"/>
      <inertia ixx="1.425E-06" ixy="0.0" ixz="0.0" iyy="1.63E-06" iyz="-3.1E-07" izz="8.63E-07"/>
    </inertial>
    <visual>
      <geometry>
        <mesh filename="package://xarm_description/meshes/gripper/lite/visual/finger1.stl"/>
      </geometry>
      <origin rpy="0 0 0" xyz="0 0 0"/>
      <material name="White"/>
    </visual>
    <collision>
      <geometry>
        <mesh filename="package://xarm_description/meshes/gripper/lite/collision/finger1.stl"/>
      </geometry>
      <origin rpy="0 0 0" xyz="0 0 0"/>
    </collision>
  </link>
  <joint name="finger_joint2" type="prismatic">
    <parent link="uflite_gripper_link"/>
    <child link="uflite_finger2"/>
    <origin rpy="0 0 0" xyz="0 0 0.0543"/>
    <axis xyz="0 -1 0"/>
    <limit effort="5" lower="0" upper="0.0089" velocity="2"/>
    <mimic joint="finger_joint1" multiplier="1" offset="0"/>
  </joint>
  <link name="uflite_finger2">
    <inertial>
      <origin rpy="0 0 0" xyz="0.0 -0.01 0.0086"/>
      <mass value="0.0163"/>
      <inertia ixx="1.425E-06" ixy="0.0" ixz="0.0" iyy="1.63E-06" iyz="3.1E-07" izz="8.63E-07"/>
    </inertial>
    <visual>
      <geometry>
        <mesh filename="package://xarm_description/meshes/gripper/lite/visual/finger2.stl"/>
      </geometry>
      <origin rpy="0 0 0" xyz="0 0 0"/>
      <material name="White"/>
    </visual>
    <collision>
      <geometry>
        <mesh filename="package://xarm_description/meshes/gripper/lite/collision/finger2.stl"/>
      </geometry>
      <origin rpy="0 0 0" xyz="0 0 0"/>
    </collision>
  </link>
  <link name="link_tcp"/>
  <joint name="joint_tcp" type="fixed">
    <origin rpy="0 0 0" xyz="0 0 0.0836"/>
    <parent link="uflite_gripper_link"/>
    <child link="link_tcp"/>
  </joint>
</robot>
